2022-02-05 22:35:16,825 ERROR: Exception on /api/users [POST] [in /Library/Frameworks/Python.framework/Versions/3.9/lib/python3.9/site-packages/flask/app.py:1457]
Traceback (most recent call last):
  File "/Library/Frameworks/Python.framework/Versions/3.9/lib/python3.9/site-packages/flask/app.py", line 2073, in wsgi_app
    response = self.full_dispatch_request()
  File "/Library/Frameworks/Python.framework/Versions/3.9/lib/python3.9/site-packages/flask/app.py", line 1518, in full_dispatch_request
    rv = self.handle_user_exception(e)
  File "/Library/Frameworks/Python.framework/Versions/3.9/lib/python3.9/site-packages/flask/app.py", line 1516, in full_dispatch_request
    rv = self.dispatch_request()
  File "/Library/Frameworks/Python.framework/Versions/3.9/lib/python3.9/site-packages/flask/app.py", line 1502, in dispatch_request
    return self.ensure_sync(self.view_functions[rule.endpoint])(**req.view_args)
  File "/Users/ndufitimana/Desktop/ScheduLit/app/api/users.py", line 24, in create_user
    if User.query.filter_by(username=data['username']):
AttributeError: 'str' object has no attribute 'first'
2022-02-05 22:36:03,325 ERROR: Exception on /api/users [POST] [in /Library/Frameworks/Python.framework/Versions/3.9/lib/python3.9/site-packages/flask/app.py:1457]
Traceback (most recent call last):
  File "/Library/Frameworks/Python.framework/Versions/3.9/lib/python3.9/site-packages/flask/app.py", line 2073, in wsgi_app
    response = self.full_dispatch_request()
  File "/Library/Frameworks/Python.framework/Versions/3.9/lib/python3.9/site-packages/flask/app.py", line 1518, in full_dispatch_request
    rv = self.handle_user_exception(e)
  File "/Library/Frameworks/Python.framework/Versions/3.9/lib/python3.9/site-packages/flask/app.py", line 1516, in full_dispatch_request
    rv = self.dispatch_request()
  File "/Library/Frameworks/Python.framework/Versions/3.9/lib/python3.9/site-packages/flask/app.py", line 1502, in dispatch_request
    return self.ensure_sync(self.view_functions[rule.endpoint])(**req.view_args)
  File "/Users/ndufitimana/Desktop/ScheduLit/app/api/users.py", line 24, in create_user
    if User.query.filter_by(username=data['username']):
AttributeError: 'str' object has no attribute 'first'
2022-02-05 22:36:26,483 INFO: courseScheduler startup [in /Users/ndufitimana/Desktop/ScheduLit/app/__init__.py:76]
2022-02-05 22:37:35,242 INFO: courseScheduler startup [in /Users/ndufitimana/Desktop/ScheduLit/app/__init__.py:76]
2022-02-06 10:17:29,902 INFO: courseScheduler startup [in /Users/ndufitimana/Desktop/ScheduLit/app/__init__.py:76]
2022-02-06 10:17:47,495 INFO: courseScheduler startup [in /Users/ndufitimana/Desktop/ScheduLit/app/__init__.py:76]
2022-02-06 10:18:03,152 INFO: courseScheduler startup [in /Users/ndufitimana/Desktop/ScheduLit/app/__init__.py:76]
2022-02-06 10:21:46,786 ERROR: Exception on /api/users/2 [PUT] [in /Library/Frameworks/Python.framework/Versions/3.9/lib/python3.9/site-packages/flask/app.py:1457]
Traceback (most recent call last):
  File "/Library/Frameworks/Python.framework/Versions/3.9/lib/python3.9/site-packages/flask/app.py", line 2073, in wsgi_app
    response = self.full_dispatch_request()
  File "/Library/Frameworks/Python.framework/Versions/3.9/lib/python3.9/site-packages/flask/app.py", line 1518, in full_dispatch_request
    rv = self.handle_user_exception(e)
  File "/Library/Frameworks/Python.framework/Versions/3.9/lib/python3.9/site-packages/flask/app.py", line 1516, in full_dispatch_request
    rv = self.dispatch_request()
  File "/Library/Frameworks/Python.framework/Versions/3.9/lib/python3.9/site-packages/flask/app.py", line 1502, in dispatch_request
    return self.ensure_sync(self.view_functions[rule.endpoint])(**req.view_args)
  File "/Users/ndufitimana/Desktop/ScheduLit/app/api/users.py", line 44, in update_user
    if 'username' in data and data['username'] != user.username and \
TypeError: argument of type 'method' is not iterable
2022-02-06 10:22:52,455 ERROR: Exception on /api/users/2 [PUT] [in /Library/Frameworks/Python.framework/Versions/3.9/lib/python3.9/site-packages/flask/app.py:1457]
Traceback (most recent call last):
  File "/Library/Frameworks/Python.framework/Versions/3.9/lib/python3.9/site-packages/flask/app.py", line 2073, in wsgi_app
    response = self.full_dispatch_request()
  File "/Library/Frameworks/Python.framework/Versions/3.9/lib/python3.9/site-packages/flask/app.py", line 1518, in full_dispatch_request
    rv = self.handle_user_exception(e)
  File "/Library/Frameworks/Python.framework/Versions/3.9/lib/python3.9/site-packages/flask/app.py", line 1516, in full_dispatch_request
    rv = self.dispatch_request()
  File "/Library/Frameworks/Python.framework/Versions/3.9/lib/python3.9/site-packages/flask/app.py", line 1502, in dispatch_request
    return self.ensure_sync(self.view_functions[rule.endpoint])(**req.view_args)
  File "/Users/ndufitimana/Desktop/ScheduLit/app/api/users.py", line 44, in update_user
    if 'username' in data and data['username'] != user.username and \
TypeError: argument of type 'method' is not iterable
2022-02-06 10:23:01,907 INFO: courseScheduler startup [in /Users/ndufitimana/Desktop/ScheduLit/app/__init__.py:76]
2022-02-06 10:35:11,498 INFO: courseScheduler startup [in /Users/ndufitimana/Desktop/ScheduLit/app/__init__.py:76]
2022-02-06 10:35:47,118 INFO: courseScheduler startup [in /Users/ndufitimana/Desktop/ScheduLit/app/__init__.py:76]
2022-02-06 10:40:44,758 INFO: courseScheduler startup [in /Users/ndufitimana/Desktop/ScheduLit/app/__init__.py:76]
2022-02-06 10:41:07,495 INFO: courseScheduler startup [in /Users/ndufitimana/Desktop/ScheduLit/app/__init__.py:76]
2022-02-06 10:54:50,328 INFO: courseScheduler startup [in /Users/ndufitimana/Desktop/ScheduLit/app/__init__.py:76]
2022-02-06 10:57:45,691 INFO: courseScheduler startup [in /Users/ndufitimana/Desktop/ScheduLit/app/__init__.py:76]
2022-02-06 10:57:50,615 ERROR: Exception on /api/tokens [POST] [in /Library/Frameworks/Python.framework/Versions/3.9/lib/python3.9/site-packages/flask/app.py:1457]
Traceback (most recent call last):
  File "/Library/Frameworks/Python.framework/Versions/3.9/lib/python3.9/site-packages/flask/app.py", line 2073, in wsgi_app
    response = self.full_dispatch_request()
  File "/Library/Frameworks/Python.framework/Versions/3.9/lib/python3.9/site-packages/flask/app.py", line 1518, in full_dispatch_request
    rv = self.handle_user_exception(e)
  File "/Library/Frameworks/Python.framework/Versions/3.9/lib/python3.9/site-packages/flask/app.py", line 1516, in full_dispatch_request
    rv = self.dispatch_request()
  File "/Library/Frameworks/Python.framework/Versions/3.9/lib/python3.9/site-packages/flask/app.py", line 1502, in dispatch_request
    return self.ensure_sync(self.view_functions[rule.endpoint])(**req.view_args)
  File "/Library/Frameworks/Python.framework/Versions/3.9/lib/python3.9/site-packages/flask_httpauth.py", line 159, in decorated
    user = self.authenticate(auth, password)
  File "/Library/Frameworks/Python.framework/Versions/3.9/lib/python3.9/site-packages/flask_httpauth.py", line 240, in authenticate
    return self.ensure_sync(self.verify_password_callback)(
  File "/Users/ndufitimana/Desktop/ScheduLit/app/api/auth.py", line 10, in verify_password
    user = User.query.filter_by(username).firs()
TypeError: filter_by() takes 1 positional argument but 2 were given
2022-02-06 10:58:44,362 INFO: courseScheduler startup [in /Users/ndufitimana/Desktop/ScheduLit/app/__init__.py:76]
2022-02-06 10:58:49,190 ERROR: Exception on /api/tokens [POST] [in /Library/Frameworks/Python.framework/Versions/3.9/lib/python3.9/site-packages/flask/app.py:1457]
Traceback (most recent call last):
  File "/Library/Frameworks/Python.framework/Versions/3.9/lib/python3.9/site-packages/flask/app.py", line 2073, in wsgi_app
    response = self.full_dispatch_request()
  File "/Library/Frameworks/Python.framework/Versions/3.9/lib/python3.9/site-packages/flask/app.py", line 1518, in full_dispatch_request
    rv = self.handle_user_exception(e)
  File "/Library/Frameworks/Python.framework/Versions/3.9/lib/python3.9/site-packages/flask/app.py", line 1516, in full_dispatch_request
    rv = self.dispatch_request()
  File "/Library/Frameworks/Python.framework/Versions/3.9/lib/python3.9/site-packages/flask/app.py", line 1502, in dispatch_request
    return self.ensure_sync(self.view_functions[rule.endpoint])(**req.view_args)
  File "/Library/Frameworks/Python.framework/Versions/3.9/lib/python3.9/site-packages/flask_httpauth.py", line 159, in decorated
    user = self.authenticate(auth, password)
  File "/Library/Frameworks/Python.framework/Versions/3.9/lib/python3.9/site-packages/flask_httpauth.py", line 240, in authenticate
    return self.ensure_sync(self.verify_password_callback)(
  File "/Users/ndufitimana/Desktop/ScheduLit/app/api/auth.py", line 10, in verify_password
    user = User.query.filter_by(username).first()
TypeError: filter_by() takes 1 positional argument but 2 were given
2022-02-06 10:59:24,948 INFO: courseScheduler startup [in /Users/ndufitimana/Desktop/ScheduLit/app/__init__.py:76]
2022-02-06 11:16:54,661 INFO: courseScheduler startup [in /Users/ndufitimana/Desktop/ScheduLit/app/__init__.py:76]
