2022-02-01 17:28:39,539 ERROR: Exception on /user/nelson [GET] [in /Library/Frameworks/Python.framework/Versions/3.9/lib/python3.9/site-packages/flask/app.py:1457]
Traceback (most recent call last):
  File "/Library/Frameworks/Python.framework/Versions/3.9/lib/python3.9/site-packages/flask/app.py", line 2073, in wsgi_app
    response = self.full_dispatch_request()
  File "/Library/Frameworks/Python.framework/Versions/3.9/lib/python3.9/site-packages/flask/app.py", line 1518, in full_dispatch_request
    rv = self.handle_user_exception(e)
  File "/Library/Frameworks/Python.framework/Versions/3.9/lib/python3.9/site-packages/flask/app.py", line 1516, in full_dispatch_request
    rv = self.dispatch_request()
  File "/Library/Frameworks/Python.framework/Versions/3.9/lib/python3.9/site-packages/flask/app.py", line 1502, in dispatch_request
    return self.ensure_sync(self.view_functions[rule.endpoint])(**req.view_args)
  File "/Library/Frameworks/Python.framework/Versions/3.9/lib/python3.9/site-packages/flask_login/utils.py", line 272, in decorated_view
    return func(*args, **kwargs)
  File "/Users/ndufitimana/Desktop/ScheduLit/app/main/routes.py", line 83, in user
    return render_template('user.html', user=user, courses = courses, form =form)
  File "/Library/Frameworks/Python.framework/Versions/3.9/lib/python3.9/site-packages/flask/templating.py", line 147, in render_template
    return _render(
  File "/Library/Frameworks/Python.framework/Versions/3.9/lib/python3.9/site-packages/flask/templating.py", line 128, in _render
    rv = template.render(context)
  File "/Library/Frameworks/Python.framework/Versions/3.9/lib/python3.9/site-packages/jinja2/environment.py", line 1291, in render
    self.environment.handle_exception()
  File "/Library/Frameworks/Python.framework/Versions/3.9/lib/python3.9/site-packages/jinja2/environment.py", line 925, in handle_exception
    raise rewrite_traceback_stack(source=source)
  File "/Users/ndufitimana/Desktop/ScheduLit/app/templates/user.html", line 1, in top-level template code
    {% extends "base.html" %}
  File "/Users/ndufitimana/Desktop/ScheduLit/app/templates/base.html", line 1, in top-level template code
    {%extends "bootstrap/base.html"%}
  File "/Library/Frameworks/Python.framework/Versions/3.9/lib/python3.9/site-packages/flask_bootstrap/templates/bootstrap/base.html", line 1, in top-level template code
    {% block doc -%}
  File "/Library/Frameworks/Python.framework/Versions/3.9/lib/python3.9/site-packages/flask_bootstrap/templates/bootstrap/base.html", line 4, in block 'doc'
    {%- block html %}
  File "/Library/Frameworks/Python.framework/Versions/3.9/lib/python3.9/site-packages/flask_bootstrap/templates/bootstrap/base.html", line 20, in block 'html'
    {% block body -%}
  File "/Library/Frameworks/Python.framework/Versions/3.9/lib/python3.9/site-packages/flask_bootstrap/templates/bootstrap/base.html", line 23, in block 'body'
    {% block content -%}
  File "/Users/ndufitimana/Desktop/ScheduLit/app/templates/base.html", line 52, in block 'content'
    {% block app_content %}{% endblock %}
  File "/Users/ndufitimana/Desktop/ScheduLit/app/templates/user.html", line 14, in block 'app_content'
    <p><a href="{{ url_for('edit_profile') }}">Edit your profile</a></p>
  File "/Library/Frameworks/Python.framework/Versions/3.9/lib/python3.9/site-packages/flask/helpers.py", line 338, in url_for
    return appctx.app.handle_url_build_error(error, endpoint, values)
  File "/Library/Frameworks/Python.framework/Versions/3.9/lib/python3.9/site-packages/flask/helpers.py", line 325, in url_for
    rv = url_adapter.build(
  File "/Library/Frameworks/Python.framework/Versions/3.9/lib/python3.9/site-packages/werkzeug/routing.py", line 2314, in build
    raise BuildError(endpoint, values, method, self)
werkzeug.routing.BuildError: Could not build url for endpoint 'edit_profile'. Did you mean 'main.edit_profile' instead?
2022-02-01 17:30:12,848 INFO: courseScheduler startup [in /Users/ndufitimana/Desktop/ScheduLit/app/__init__.py:72]
2022-02-01 17:31:32,627 INFO: courseScheduler startup [in /Users/ndufitimana/Desktop/ScheduLit/app/__init__.py:72]
2022-02-01 17:32:05,991 INFO: courseScheduler startup [in /Users/ndufitimana/Desktop/ScheduLit/app/__init__.py:72]
2022-02-02 19:18:28,587 INFO: courseScheduler startup [in /Users/ndufitimana/Desktop/ScheduLit/app/__init__.py:72]
2022-02-02 22:27:43,715 INFO: courseScheduler startup [in /Users/ndufitimana/Desktop/ScheduLit/app/__init__.py:72]
2022-02-05 20:56:03,988 INFO: courseScheduler startup [in /Users/ndufitimana/Desktop/ScheduLit/app/__init__.py:76]
2022-02-05 21:11:44,427 INFO: courseScheduler startup [in /Users/ndufitimana/Desktop/ScheduLit/app/__init__.py:76]
2022-02-05 21:14:27,343 INFO: courseScheduler startup [in /Users/ndufitimana/Desktop/ScheduLit/app/__init__.py:76]
2022-02-05 21:34:01,152 INFO: courseScheduler startup [in /Users/ndufitimana/Desktop/ScheduLit/app/__init__.py:76]
2022-02-05 21:35:13,795 INFO: courseScheduler startup [in /Users/ndufitimana/Desktop/ScheduLit/app/__init__.py:76]
2022-02-05 21:40:18,904 INFO: courseScheduler startup [in /Users/ndufitimana/Desktop/ScheduLit/app/__init__.py:76]
2022-02-05 21:45:04,119 INFO: courseScheduler startup [in /Users/ndufitimana/Desktop/ScheduLit/app/__init__.py:76]
2022-02-05 21:54:04,675 INFO: courseScheduler startup [in /Users/ndufitimana/Desktop/ScheduLit/app/__init__.py:76]
2022-02-05 22:00:57,854 INFO: courseScheduler startup [in /Users/ndufitimana/Desktop/ScheduLit/app/__init__.py:76]
2022-02-05 22:08:31,545 INFO: courseScheduler startup [in /Users/ndufitimana/Desktop/ScheduLit/app/__init__.py:76]
2022-02-05 22:10:28,592 INFO: courseScheduler startup [in /Users/ndufitimana/Desktop/ScheduLit/app/__init__.py:76]
2022-02-05 22:21:27,893 INFO: courseScheduler startup [in /Users/ndufitimana/Desktop/ScheduLit/app/__init__.py:76]
2022-02-05 22:24:12,707 ERROR: Exception on /api/users [POST] [in /Library/Frameworks/Python.framework/Versions/3.9/lib/python3.9/site-packages/flask/app.py:1457]
Traceback (most recent call last):
  File "/Library/Frameworks/Python.framework/Versions/3.9/lib/python3.9/site-packages/flask/app.py", line 2073, in wsgi_app
    response = self.full_dispatch_request()
  File "/Library/Frameworks/Python.framework/Versions/3.9/lib/python3.9/site-packages/flask/app.py", line 1518, in full_dispatch_request
    rv = self.handle_user_exception(e)
  File "/Library/Frameworks/Python.framework/Versions/3.9/lib/python3.9/site-packages/flask/app.py", line 1516, in full_dispatch_request
    rv = self.dispatch_request()
  File "/Library/Frameworks/Python.framework/Versions/3.9/lib/python3.9/site-packages/flask/app.py", line 1502, in dispatch_request
    return self.ensure_sync(self.view_functions[rule.endpoint])(**req.view_args)
  File "/Users/ndufitimana/Desktop/ScheduLit/app/api/users.py", line 24, in create_user
    if User.query.filter_by(username= data['username'].first()):
AttributeError: 'str' object has no attribute 'first'
2022-02-05 22:26:42,346 ERROR: Exception on /api/users [POST] [in /Library/Frameworks/Python.framework/Versions/3.9/lib/python3.9/site-packages/flask/app.py:1457]
Traceback (most recent call last):
  File "/Library/Frameworks/Python.framework/Versions/3.9/lib/python3.9/site-packages/flask/app.py", line 2073, in wsgi_app
    response = self.full_dispatch_request()
  File "/Library/Frameworks/Python.framework/Versions/3.9/lib/python3.9/site-packages/flask/app.py", line 1518, in full_dispatch_request
    rv = self.handle_user_exception(e)
  File "/Library/Frameworks/Python.framework/Versions/3.9/lib/python3.9/site-packages/flask/app.py", line 1516, in full_dispatch_request
    rv = self.dispatch_request()
  File "/Library/Frameworks/Python.framework/Versions/3.9/lib/python3.9/site-packages/flask/app.py", line 1502, in dispatch_request
    return self.ensure_sync(self.view_functions[rule.endpoint])(**req.view_args)
  File "/Users/ndufitimana/Desktop/ScheduLit/app/api/users.py", line 24, in create_user
    if User.query.filter_by(username= data['username']).first():
AttributeError: 'str' object has no attribute 'first'
2022-02-05 22:31:33,839 ERROR: Exception on /api/users [POST] [in /Library/Frameworks/Python.framework/Versions/3.9/lib/python3.9/site-packages/flask/app.py:1457]
Traceback (most recent call last):
  File "/Library/Frameworks/Python.framework/Versions/3.9/lib/python3.9/site-packages/flask/app.py", line 2073, in wsgi_app
    response = self.full_dispatch_request()
  File "/Library/Frameworks/Python.framework/Versions/3.9/lib/python3.9/site-packages/flask/app.py", line 1518, in full_dispatch_request
    rv = self.handle_user_exception(e)
  File "/Library/Frameworks/Python.framework/Versions/3.9/lib/python3.9/site-packages/flask/app.py", line 1516, in full_dispatch_request
    rv = self.dispatch_request()
  File "/Library/Frameworks/Python.framework/Versions/3.9/lib/python3.9/site-packages/flask/app.py", line 1502, in dispatch_request
    return self.ensure_sync(self.view_functions[rule.endpoint])(**req.view_args)
  File "/Users/ndufitimana/Desktop/ScheduLit/app/api/users.py", line 24, in create_user
    if User.query.filter_by(username= data['username']).first():
AttributeError: 'str' object has no attribute 'first'
