2022-01-16 15:59:05,671 INFO: courseScheduler startup [in /Users/ndufitimana/Desktop/myapp/app/__init__.py:47]
2022-01-16 16:02:09,263 INFO: courseScheduler startup [in /Users/ndufitimana/Desktop/myapp/app/__init__.py:47]
2022-01-16 16:02:19,792 INFO: courseScheduler startup [in /Users/ndufitimana/Desktop/myapp/app/__init__.py:47]
2022-01-16 16:03:49,001 INFO: courseScheduler startup [in /Users/ndufitimana/Desktop/myapp/app/__init__.py:47]
2022-01-16 16:04:30,248 INFO: courseScheduler startup [in /Users/ndufitimana/Desktop/myapp/app/__init__.py:47]
2022-01-16 16:12:58,458 INFO: courseScheduler startup [in /Users/ndufitimana/Desktop/myapp/app/__init__.py:47]
2022-01-16 16:13:32,915 INFO: courseScheduler startup [in /Users/ndufitimana/Desktop/myapp/app/__init__.py:47]
2022-01-16 18:08:24,685 INFO: courseScheduler startup [in /Users/ndufitimana/Desktop/myapp/app/__init__.py:47]
2022-01-16 18:11:10,803 INFO: courseScheduler startup [in /Users/ndufitimana/Desktop/myapp/app/__init__.py:47]
2022-01-16 18:18:48,030 INFO: courseScheduler startup [in /Users/ndufitimana/Desktop/myapp/app/__init__.py:47]
2022-01-16 18:20:22,634 INFO: courseScheduler startup [in /Users/ndufitimana/Desktop/myapp/app/__init__.py:47]
2022-01-22 10:54:02,285 INFO: courseScheduler startup [in /Users/ndufitimana/Desktop/ScheduLit/app/__init__.py:47]
2022-01-22 10:54:23,616 INFO: courseScheduler startup [in /Users/ndufitimana/Desktop/ScheduLit/app/__init__.py:47]
2022-01-22 10:56:02,232 INFO: courseScheduler startup [in /Users/ndufitimana/Desktop/ScheduLit/app/__init__.py:47]
2022-01-22 10:56:36,021 INFO: courseScheduler startup [in /Users/ndufitimana/Desktop/ScheduLit/app/__init__.py:47]
2022-01-22 10:57:11,600 INFO: courseScheduler startup [in /Users/ndufitimana/Desktop/ScheduLit/app/__init__.py:47]
2022-01-22 10:57:58,394 ERROR: Exception on /add [POST] [in /Library/Frameworks/Python.framework/Versions/3.9/lib/python3.9/site-packages/flask/app.py:1457]
Traceback (most recent call last):
  File "/Library/Frameworks/Python.framework/Versions/3.9/lib/python3.9/site-packages/sqlalchemy/engine/base.py", line 1702, in _execute_context
    context = constructor(
  File "/Library/Frameworks/Python.framework/Versions/3.9/lib/python3.9/site-packages/sqlalchemy/engine/default.py", line 1070, in _init_compiled
    param = [
  File "/Library/Frameworks/Python.framework/Versions/3.9/lib/python3.9/site-packages/sqlalchemy/engine/default.py", line 1071, in <listcomp>
    processors[key](compiled_params[key])
  File "/Library/Frameworks/Python.framework/Versions/3.9/lib/python3.9/site-packages/sqlalchemy/dialects/sqlite/base.py", line 1003, in process
    raise TypeError(
TypeError: SQLite DateTime type only accepts Python datetime and date objects as input.

The above exception was the direct cause of the following exception:

Traceback (most recent call last):
  File "/Library/Frameworks/Python.framework/Versions/3.9/lib/python3.9/site-packages/flask/app.py", line 2073, in wsgi_app
    response = self.full_dispatch_request()
  File "/Library/Frameworks/Python.framework/Versions/3.9/lib/python3.9/site-packages/flask/app.py", line 1518, in full_dispatch_request
    rv = self.handle_user_exception(e)
  File "/Library/Frameworks/Python.framework/Versions/3.9/lib/python3.9/site-packages/flask/app.py", line 1516, in full_dispatch_request
    rv = self.dispatch_request()
  File "/Library/Frameworks/Python.framework/Versions/3.9/lib/python3.9/site-packages/flask/app.py", line 1502, in dispatch_request
    return self.ensure_sync(self.view_functions[rule.endpoint])(**req.view_args)
  File "/Library/Frameworks/Python.framework/Versions/3.9/lib/python3.9/site-packages/flask_login/utils.py", line 272, in decorated_view
    return func(*args, **kwargs)
  File "/Users/ndufitimana/Desktop/ScheduLit/app/routes.py", line 63, in addCourse
    db.session.commit()
  File "<string>", line 2, in commit
  File "/Library/Frameworks/Python.framework/Versions/3.9/lib/python3.9/site-packages/sqlalchemy/orm/session.py", line 1431, in commit
    self._transaction.commit(_to_root=self.future)
  File "/Library/Frameworks/Python.framework/Versions/3.9/lib/python3.9/site-packages/sqlalchemy/orm/session.py", line 829, in commit
    self._prepare_impl()
  File "/Library/Frameworks/Python.framework/Versions/3.9/lib/python3.9/site-packages/sqlalchemy/orm/session.py", line 808, in _prepare_impl
    self.session.flush()
  File "/Library/Frameworks/Python.framework/Versions/3.9/lib/python3.9/site-packages/sqlalchemy/orm/session.py", line 3363, in flush
    self._flush(objects)
  File "/Library/Frameworks/Python.framework/Versions/3.9/lib/python3.9/site-packages/sqlalchemy/orm/session.py", line 3503, in _flush
    transaction.rollback(_capture_exception=True)
  File "/Library/Frameworks/Python.framework/Versions/3.9/lib/python3.9/site-packages/sqlalchemy/util/langhelpers.py", line 70, in __exit__
    compat.raise_(
  File "/Library/Frameworks/Python.framework/Versions/3.9/lib/python3.9/site-packages/sqlalchemy/util/compat.py", line 207, in raise_
    raise exception
  File "/Library/Frameworks/Python.framework/Versions/3.9/lib/python3.9/site-packages/sqlalchemy/orm/session.py", line 3463, in _flush
    flush_context.execute()
  File "/Library/Frameworks/Python.framework/Versions/3.9/lib/python3.9/site-packages/sqlalchemy/orm/unitofwork.py", line 456, in execute
    rec.execute(self)
  File "/Library/Frameworks/Python.framework/Versions/3.9/lib/python3.9/site-packages/sqlalchemy/orm/unitofwork.py", line 630, in execute
    util.preloaded.orm_persistence.save_obj(
  File "/Library/Frameworks/Python.framework/Versions/3.9/lib/python3.9/site-packages/sqlalchemy/orm/persistence.py", line 244, in save_obj
    _emit_insert_statements(
  File "/Library/Frameworks/Python.framework/Versions/3.9/lib/python3.9/site-packages/sqlalchemy/orm/persistence.py", line 1221, in _emit_insert_statements
    result = connection._execute_20(
  File "/Library/Frameworks/Python.framework/Versions/3.9/lib/python3.9/site-packages/sqlalchemy/engine/base.py", line 1614, in _execute_20
    return meth(self, args_10style, kwargs_10style, execution_options)
  File "/Library/Frameworks/Python.framework/Versions/3.9/lib/python3.9/site-packages/sqlalchemy/sql/elements.py", line 325, in _execute_on_connection
    return connection._execute_clauseelement(
  File "/Library/Frameworks/Python.framework/Versions/3.9/lib/python3.9/site-packages/sqlalchemy/engine/base.py", line 1481, in _execute_clauseelement
    ret = self._execute_context(
  File "/Library/Frameworks/Python.framework/Versions/3.9/lib/python3.9/site-packages/sqlalchemy/engine/base.py", line 1708, in _execute_context
    self._handle_dbapi_exception(
  File "/Library/Frameworks/Python.framework/Versions/3.9/lib/python3.9/site-packages/sqlalchemy/engine/base.py", line 2026, in _handle_dbapi_exception
    util.raise_(
  File "/Library/Frameworks/Python.framework/Versions/3.9/lib/python3.9/site-packages/sqlalchemy/util/compat.py", line 207, in raise_
    raise exception
  File "/Library/Frameworks/Python.framework/Versions/3.9/lib/python3.9/site-packages/sqlalchemy/engine/base.py", line 1702, in _execute_context
    context = constructor(
  File "/Library/Frameworks/Python.framework/Versions/3.9/lib/python3.9/site-packages/sqlalchemy/engine/default.py", line 1070, in _init_compiled
    param = [
  File "/Library/Frameworks/Python.framework/Versions/3.9/lib/python3.9/site-packages/sqlalchemy/engine/default.py", line 1071, in <listcomp>
    processors[key](compiled_params[key])
  File "/Library/Frameworks/Python.framework/Versions/3.9/lib/python3.9/site-packages/sqlalchemy/dialects/sqlite/base.py", line 1003, in process
    raise TypeError(
sqlalchemy.exc.StatementError: (builtins.TypeError) SQLite DateTime type only accepts Python datetime and date objects as input.
[SQL: INSERT INTO course (course, timestamp, building, user_id) VALUES (?, ?, ?, ?)]
[parameters: [{'building': 'SCI 101', 'timestamp': datetime.time(16, 30), 'course': 'aaaa', 'user_id': 1}]]
2022-01-22 11:39:41,735 INFO: courseScheduler startup [in /Users/ndufitimana/Desktop/ScheduLit/app/__init__.py:47]
